Workbook

Sheet Claude Log
A1: Turno | B1: Fecha | C1: Petición del usuario | D1: Acción realizada | E1: Detalles | F1: Resultado
A2: 1 | B2: 46179 | C2: Hacer la parte de los jueces más intuitiva y fácil para dar notas, y dejar datos listos para una futura app móvil/tablet. | D2: Rediseño de hojas JUEZ_1/2/3: reorden visual de columnas, desplegables y formato. | E2: Layout A=Jogo,B=Fase,C=Jug.A,D=Jug.B,E=Toque,F=NOTA(lista 0-5 paso 0.5),G=MÁS FLOJO(A/B). Validación de datos, formato 0.0, letra grande, filas altas, CF resalta jogos sin puntuar. Corregido A5 que tenía espacios en vez de J01. | F2: 3 hojas de juez listas y consistentes; pendientes resaltados en rojo claro.
A3: 2 | B3: 46179 | C3: Cambiar el desplegable de la nota a saltos de 0.1. | D3: Reemplazada la lista de validación de NOTA en JUEZ_1/2/3. | E3: Lista F5:F34 ahora 0.0–5.0 paso 0.1 (51 valores), formato 0.0. Restaurado título A1 de JUEZ_2 que tenía texto de prueba. | F3: Aplicado a las 3 hojas de juez.
A4: 3 | B4: 46179 | C4: Sustituir la columna A/B por un desplegable de puntos a quitar (0.1-5) junto a cada jugador. | D4: Rediseño de columnas en JUEZ_1/2/3 con 'Quita A' y 'Quita B'. | E4: Nuevo orden: C=Jug.A, D=Quita A, E=Jug.B, F=Quita B, G=Toque, H=MI NOTA. Quita A/B = lista 0.1-5.0 paso 0.1 (naranja). NOTA = lista 0.0-5.0 (amarillo). Quitada columna A/B previa. Títulos e instrucciones actualizados. | F4: Aplicado a las 3 hojas. Pendiente opcional: columna de nota final por jugador (nota − descuento).
A5: 4 | B5: 46179 | C5: Añadir cálculo automático de la nota final por jugador. | D5: Añadidas columnas I=Final A y J=Final B en JUEZ_1/2/3. | E5: I5=IF(H5="","",MAX(0,H5-N(D5))); J5 análogo con F5. Resta el descuento a la nota, mínimo 0, vacío si no hay nota. Formato verde 0.0. | F5: Aplicado a las 3 hojas y verificadas las fórmulas.
A6: 5 | B6: 46179 | C6: Que al sumar notas se avancen automáticamente los clasificados a la fase siguiente. | D6: Re-cableado del motor MESA_JOGOS al nuevo layout de los jueces; criterio = mayor nota final. | E6: I-N ahora leen Final A/B (col 9/10) de JUEZ_1/2/3. O=Total A, P=Total B (suma 3 jueces). Q (Ganador) cambiado a 'gana MAYOR total' con BYE/empate. Avance y autopoblado de Octavas/Semis/Final ya existían y siguen activos. Probado con J25 (Soba 11.5 vs Camioneiro 10 -> Soba a Final) y limpiadas las notas de prueba. | F6: Avance de fase 100% automático verificado de extremo a extremo.
A7: 6 | B7: 46179 | C7: Explicar/montar el avance por fases: el torneo es ranking por puntos (32->16->8->4->1) con reinicio de suma cada fase; premio al mejor juego solo en la Final. | D7: Creada hoja CLASIFICACION para la Fase 32->16 (ranking por puntos). | E7: A-C: 32 jugadores + puntos (=MESA_JOGOS O/P) + clave de orden (BYE al fondo). E-H: ranking con LARGE/INDEX/MATCH, top16=CLASIFICA, empate frontera='Empate (mesa)', línea de corte roja. CF verde/amarillo. Probado con 8 reales y limpiado. | F7: Fase 32->16 lista y verificada. Pendiente: Octavas 16->8, Semis 8->4, Final 4->1 + premio mejor juego (fase por fase).
A8: 7 | B8: 46179 | C8: Continuar el sistema por fases: montar Octavas (16->8). | D8: Añadido bloque OCTAVAS en CLASIFICACION y emparejamiento 1v16 en MESA_JOGOS. | E8: MESA_JOGOS J17-J24 (filas 22-29): F=puesto k, G=puesto 17-k desde CLASIFICACION!F5:F20. Bloque Octavas en CLASIFICACION cols J-Q: datos crudos (=MESA O/P filas 22-29), clave con BYE al fondo, ranking LARGE/INDEX/MATCH, top8=CLASIFICA, empate frontera puesto8/9, corte rojo fila12, CF verde/amarillo. Suma reiniciada por fase. | F8: Octavas listo y verificado. Pendiente: Semifinal 8->4 y Final 4->1 + premio mejor juego.
A9: 8 | B9: 46179 | C9: Continuar sistema por fases: montar Semifinal (8->4). | D9: Emparejamiento Semifinal en MESA_JOGOS y bloque SEMIFINAL en CLASIFICACION. | E9: MESA_JOGOS J25-J28 (filas 30-33): F=puesto k, G=puesto 9-k desde ranking Octavas CLASIFICACION!O5:O12 (siembra 1v8,2v7,3v6,4v5). Bloque Semifinal CLASIFICACION cols S-Z: datos crudos (=MESA O/P filas 30-33), clave BYE al fondo, ranking LARGE/INDEX/MATCH, top4=CLASIFICA, empate frontera puesto4/5, corte rojo fila8, CF. Suma reiniciada. | F9: Semifinal lista y verificada (Soba vs Mãozinha etc.). Pendiente: Final 4->1 + premio mejor juego.
A10: 9 | B10: 46179 | C10: Montar la Final (4->1) con campeón y premio al mejor juego. | D10: Emparejamiento Final en MESA_JOGOS + bloques FINAL y PREMIO en CLASIFICACION. | E10: MESA_JOGOS J29-J30 (filas 34-35): F/G = puesto1v4, 2v3 desde ranking Semifinal X5:X8. CLASIFICACION cols AB-AI: ranking 4 finalistas, AI=Resultado (1º=CAMPEÓN o 'Empate 1º (mesa)', 2º Subcampeón, 3º/4º). Premio mejor juego AB10-AF13: nota jogo=O+P, marca '🥇 MEJOR JUEGO' al mayor. CF dorado. Verificado e2e: con notas Surikato campeón al penalizar a Indio; mejor juego J29(30)>J30(24). Notas de prueba limpiadas (H/D/F). | F10: SISTEMA COMPLETO 32->16->8->4->1 + premio mejor juego. Todo automático y verificado.
A11: 10 | B11: 46179 | C11: Montar las 8 categorías del evento (cada una torneo completo con sus toques), jueces con una sola hoja apilada. | D11: CONFIG_CAT + JUEZ_1/2/3 reconstruidas (8 cat. apiladas) + motor CLASIF_A modelo completo y validado. | E11: Modelo: cada pareja juega 1 jogo por toque por fase; puntos fase = SUMA toques × 3 jueces. JUEZ_1/2/3 idénticas, filas 3-687, mapa en blob catmap_juez. CLASIF_A: 4 bloques (Fase32 A-H top16, Octavas J-Q top8, Semis S-Z top4, Final AB-AI campeón) + premios mejor juego POR TOQUE (AB10-AG). Emparejamiento auto por fórmula 1vN. Nota es por jogo (A/B comparten, descuento los separa). Verificado e2e con 16 parejas reales. | F11: Cat. A completa y validada. PENDIENTE: replicar CLASIF a B,C,D,E,Baobá,Juvenil,General + emparejamientos en juez + dashboard.
A12: 11 | B12: 46179 | C12: Completar las 8 categorías del evento con sus motores de ranking y premios por toque. | D12: Generadas CLASIF_B/C/D/E/Baoba/Juvenil/General + emparejamientos en juez + limpieza. | E12: 7 CLASIF replicadas desde el modelo CLASIF_A (4 bloques fase + premios por toque), parametrizadas por nº toques (E/Juvenil=2). Emparejamientos auto 1vN en JUEZ_1/2/3 (Octavas/Semis/Final leen ranking fase previa). Verificado sin errores de fórmula en las 7. Eliminadas hojas provisionales (JUEZ1_CATA_MODELO, CLASIF_CATA, Hoja3, Hoja4). | F12: 8 categorías completas y operativas. Quedan obsoletas MESA_JOGOS y CLASIFICACION del sistema de 1 categoría (pendiente confirmar con usuario si borrar). Faltan nombres reales (desde TORNEO_ACTIVO/formulario).
A13: 12 | B13: 46179 | C13: Borrar el sistema viejo de 1 categoría y mantener el nuevo de 8 categorías. | D13: Eliminadas MESA_JOGOS y CLASIFICACION tras verificar que no hay referencias. | E13: Comprobado que ninguna CLASIF_* nueva referencia las hojas viejas (refsToOld=[]). Borradas ambas. Libro con CONFIG_CAT, JUEZ_1/2/3 y CLASIF_A..General. Hojas originales (CONFIG, INSCRITOS_FORM, PARTICIPANTES, LLAVES_INDEX, TORNEO_ACTIVO) intactas. | F13: Sistema nuevo limpio. Pendiente: conectar nombres reales de inscritos por categoría (placeholders actuales).
A14: 13 | B14: 46179 | C14: Revisar formulario de inscripción y ampliar el sistema a género (M/F) e infantiles. | D14: Reconstruido JUEZ_1/2/3 con 16 secciones (cat×M/F)+Infantil; creados 16 motores CLASIF + CLASIF_INF. | E14: Formulario JotForm: apodo=identificador, graduación→categoría, separación por género. JUEZ_1/2/3 ahora 16 secciones (A_M..General_F) hasta ~fila 1369 + Infantil (rueda São Bento, 40 cupos). 16 hojas CLASIF_<cat>_<M/F> (4 bloques fase + premios por toque, suma toques×3 jueces, excluye placeholders A_/B_). CLASIF_INF ranking por nota (top3 medallas, mixto). Emparejamientos auto 1vN entre fases. Verificado A_M (Soba 45) e Infantil (Dentinho 15) sin errores; pruebas limpiadas. Mapa en blob catmap_juez_mf. | F14: Sistema completo: 16 torneos por categoría-género + Infantil. Pendiente: nombres reales de inscritos (auto-asignación por graduación/género desde formulario).
A16: RECUENTO POR CATEGORÍA | B16: Categoría | C16: Actuales | D16: Faltan
B17: Adulto-A · M | C17: =COUNTIF(INSCRITOS_FORM!$S$5:$S$200,"Adulto-A · Masculino") | D17: =MAX(0.32-C17) | H17: =COUNTIF(INSCRITOS_FORM!$S$5:$S$200,"Adulto-A · Masculino")
B18: Adulto-A · F | C18: =COUNTIF(INSCRITOS_FORM!$S$5:$S$200,"Adulto-A · Femenino") | D18: =MAX(0.32-C18)
B19: Adulto-B · M | C19: =COUNTIF(INSCRITOS_FORM!$S$5:$S$200,"Adulto-B · Masculino") | D19: =MAX(0.32-C19)
B20: Adulto-B · F | C20: =COUNTIF(INSCRITOS_FORM!$S$5:$S$200,"Adulto-B · Femenino") | D20: =MAX(0.32-C20)
B21: Adulto-C · M | C21: =COUNTIF(INSCRITOS_FORM!$S$5:$S$200,"Adulto-C · Masculino") | D21: =MAX(0.32-C21)
B22: Adulto-C · F | C22: =COUNTIF(INSCRITOS_FORM!$S$5:$S$200,"Adulto-C · Femenino") | D22: =MAX(0.32-C22)
B23: Adulto-D · M | C23: =COUNTIF(INSCRITOS_FORM!$S$5:$S$200,"Adulto-D · Masculino") | D23: =MAX(0.32-C23)
B24: Adulto-D · F | C24: =COUNTIF(INSCRITOS_FORM!$S$5:$S$200,"Adulto-D · Femenino") | D24: =MAX(0.32-C24)
B25: Adulto-E · M | C25: =COUNTIF(INSCRITOS_FORM!$S$5:$S$200,"Adulto-E · Masculino") | D25: =MAX(0.32-C25)
B26: Adulto-E · F | C26: =COUNTIF(INSCRITOS_FORM!$S$5:$S$200,"Adulto-E · Femenino") | D26: =MAX(0.32-C26)
B27: Baobá-Grad+ · M | C27: =COUNTIF(INSCRITOS_FORM!$S$5:$S$200,"Baobá-Graduados+ · Masculino") | D27: =MAX(0.32-C27)
B28: Baobá-Grad+ · F | C28: =COUNTIF(INSCRITOS_FORM!$S$5:$S$200,"Baobá-Graduados+ · Femenino") | D28: =MAX(0.32-C28)
B29: Juvenil · M | C29: =COUNTIF(INSCRITOS_FORM!$S$5:$S$200,"Juvenil · Masculino") | D29: =MAX(0.32-C29)
B30: Juvenil · F | C30: =COUNTIF(INSCRITOS_FORM!$S$5:$S$200,"Juvenil · Femenino") | D30: =MAX(0.32-C30)
B31: General · M | C31: =COUNTIF(INSCRITOS_FORM!$S$5:$S$200,"General · Masculino") | D31: =MAX(0.32-C31)
B32: General · F | C32: =COUNTIF(INSCRITOS_FORM!$S$5:$S$200,"General · Femenino") | D32: =MAX(0.32-C32)

Sheet MESA_JOGOS

Sheet APP_CONTROL
A1: jogo_id | B1: ronda | C1: num | D1: categoria | E1: jugador_a | F1: jugador_b | G1: corda_a | H1: corda_b | I1: toque | J1: estado | K1: ganador | L1: timestamp

Sheet APP_PUNTUACIONES
A1: jogo_id | B1: juez | C1: nota | D1: resta_a | E1: resta_b | F1: timestamp

Sheet CONFIG_CAT
A1: CONFIGURACIÓN DE CATEGORÍAS Y TOQUES
A3: # | B3: Categoría | C3: Graduación | D3: Toques (en orden) | E3: Nº toques
A4: 1 | B4: A | C4: Marrón / Marrón-Rojo (Profesores) | D4: Benguela | São Bento da Abadá | Siriuna | E4: 3
A5: 2 | B5: B | C5: Morada / Morada-Marrón (Instructores) | D5: Benguela | São Bento da Abadá | Siriuna | E5: 3
A6: 3 | B6: C | C6: Verde / Verde-Morada (Graduados) | D6: Benguela | São Bento da Abadá | Siriuna | E6: 3
A7: 4 | B7: D | C7: Azul / Azul-Verde (Graduados) | D7: Benguela | São Bento da Abadá | Siriuna | E7: 3
A8: 5 | B8: E | C8: Naranja / Naranja-Azul (Alumnos) | D8: São Bento da Abadá | Benguela | E8: 2
A9: 6 | B9: Baobá | C9: +45 años (desde Naranja) | D9: São Bento da Abadá | Benguela | Siriuna | E9: 3
A10: 7 | B10: Juvenil | C10: Desde Amarilla/Naranja | D10: São Bento da Abadá | Benguela | E10: 2
A11: 8 | B11: General | C11: Todas | D11: Benguela | São Bento da Abadá | Siriuna | E11: 3

Sheet 00_LEEME
A1: Sistema de Competición · Jogos Ibéricos Abiertos Burgos 2026 · v2 FASE 2
A2: Motor de torneo completo con modelo de puntuación Abadá (3 jueces × nota+débil)
A4: HOJAS DEL SISTEMA
A5: # | B5: Hoja | C5: Función
A6: 1 | B6: CONFIG | C6: Listas maestras: categorías, cordas, toques, parámetros
A7: 2 | B7: INSCRITOS_FORM | C7: Datos de JotForm + auto-categorización
A8: 3 | B8: PARTICIPANTES | C8: Tabla normalizada (lectura)
A9: 4 | B9: LLAVES_INDEX | C9: Catálogo de las 22 llaves con tamaño y ronda inicial
A10: 5 | B10: TORNEO_ACTIVO | C10: Selector de llave + lista de posiciones seeded (1-32)
A11: 6 | B11: MESA_JOGOS | C11: Motor: 30 jogos máx con cálculo de restas y ganador
A12: 7 | B12: JUEZ_1, JUEZ_2, JUEZ_3 | C12: Input simple para cada juez: nota (0-5) + débil
A14: MODELO DE PUNTUACIÓN ABADÁ
A15: • Cada jogo es jugado por una pareja (jugador A vs jugador B).
A16: • Cada uno de los 3 jueces puntúa el jogo de 0.0 a 5.0 con décimos.
A17: • Cada juez marca al jugador que aportó MENOS (A o B).
A18: • A ese jugador se le RESTA la nota del jogo dada por ese juez.
A19: • Resta_A = suma de notas de jueces que marcaron A · Resta_B = suma de notas de jueces que marcaron B.
A20: • Pierde el jugador con más resta total (en magnitud). El otro avanza.
A21: • Empate de restas → decisión de mesa (a veces consulta a jueces).
A23: ESTRUCTURA DE LLAVES
A24: Inscritos | B24: Tamaño llave | C24: Ronda inicial | D24: Total jogos
A25: 2-4 | B25: 4 | C25: Final (2 jogos cruzados) | D25: 2
A26: 5-8 | B26: 8 | C26: Semifinal (4 jogos) | D26: 6
A27: 9-16 | B27: 16 | C27: Octavas (8 jogos) | D27: 14
A28: 17-32 | B28: 32 | C28: Eliminatoria (16 jogos) | D28: 30
A30: LEYENDA
B31: Entrada manual
B32: Calculado por fórmula
B33: Ganador del jogo
B34: Perdedor del jogo (eliminado)

Sheet CONFIG
A1: CONFIG · Listas maestras y parámetros
A4: CATEGORÍAS DE EDAD
A5: Categoría | B5: Edad mín | C5: Edad máx | D5: Corda mín | E5: Toques permitidos
A6: Infantil | B6: 0 | C6: 11 | D6: (todas) | E6: Benguela · São Bento da Abadá
A7: Juvenil | B7: 12 | C7: 17 | D7: Amarela | E7: Benguela · São Bento da Abadá
A8: Adulto | B8: 18 | C8: 44 | D8: Laranja | E8: Benguela · São Bento da Abadá · Siriuna (desde graduados)
A9: Baobá | B9: 45 | C9: 120 | D9: Laranja | E9: Benguela · São Bento da Abadá · Siriuna (desde graduados)
A12: CATEGORÍAS ADULTO · Mapeo de corda
A13: Cat | B13: Nivel | C13: Cordas | D13: Toques
A14: A | B14: Profesores | C14: Marrom · Marrom/Vermelha | D14: Benguela · São Bento · Siriuna
A15: B | B15: Instructores | C15: Roxa · Roxa/Marrom | D15: Benguela · São Bento · Siriuna
A16: C | B16: Graduados | C16: Verde · Verde/Roxa | D16: Benguela · São Bento · Siriuna
A17: D | B17: Graduados | C17: Azul · Azul/Verde | D17: Benguela · São Bento · Siriuna
A18: E | B18: Alumnos | C18: Laranja · Laranja/Azul | D18: Benguela · São Bento da Abadá
A20: CORDAS · Orden oficial (1=más baja, 14=más alta)
A21: Orden | B21: Corda | C21: Adulto cat | D21: Baobá cat | E21: Juvenil | F21: Infantil
A39: Toque | B39: Característica | C39: Categorías
A40: Benguela | B40: Lento, jogo cercano | C40: Todas las categorías
A41: São Bento da Abadá | B41: Ritmo base medio | C41: Todas las categorías
A42: Siriuna | B42: Sin canto, alto nivel | C42: Solo desde graduados
A45: FESTIVAL CANTIGAS · Sistema individual
A46: Subcategoría | B46: Unidad | C46: Cálculo
A47: Interpretación | B47: Individual | C47: Suma 3 jueces × (0-5) → ranking, mejores avanzan
A48: Composición | B48: Individual | C48: Suma 3 jueces × (0-5) → ranking, mejores avanzan
A49: Sólo Instrumento | B49: Individual | C49: Suma 3 jueces × (0-5) → ranking, mejores avanzan
A50: Bateranga | B50: Grupo (nombre) | C50: Suma 3 jueces × (0-5) → ranking, mejores avanzan
A53: GÉNEROS
A54: Masculino
A55: Femenino
A57: PARÁMETROS DEL SISTEMA
A58: Parámetro | B58: Valor
A59: Nº jueces | B59: 3
A60: Puntuación mínima jogo | B60: 0
A61: Puntuación máxima jogo | B61: 5
A62: Decimales permitidos | B62: 1
A63: Criterio empate | B63: Decisión mesa
A64: Llave mínima | B64: 4
A65: Llave máxima | B65: 32
A66: Umbral llave 4 (max insc.) | B66: 4
A67: Umbral llave 8 (max insc.) | B67: 8
...

Sheet INSCRITOS_FORM
A1: INSCRITOS_FORM · Datos desde JotForm + Stripe
A2: Pega aquí el export de JotForm. Las columnas verdes se calculan solas.
A4: timestamp | B4: jotform_id | C4: stripe_payment_id | D4: nombre | E4: apellido | F4: apelido | G4: nombre_mostrar | H4: email | I4: telefono | J4: ciudad_pais | K4: profesor | L4: corda | M4: genero | N4: fecha_nacimiento | O4: edad | P4: categoria_edad | Q4: categoria_adulto | R4: categoria_baoba | S4: categoria_final | T4: id_llave | U4: compite_jogo | V4: compite_festival | W4: categoria_festival | X4: miembros_grupo | Y4: excepcion_mesa | Z4: talla_camiseta | AA4: importe_pagado | AB4: estado_pago | AC4: observaciones | AD4: id_participante
A5: 2025-08-10 14:10:29 | D5: Carlos | E5: Fischer | F5: Vagalume | G5: =IF(F5<>"",F5,IF(AND(D5="",E5=""),"",TRIM(D5&" "&E5))) | I5: +34 674 880 282 | J5: Curitiba-Brasil | K5: Mestre Coruja | L5: Marrom | M5: Masculino | N5: 30945 | O5: =IF(N5="","",DATEDIF(N5,TODAY(),"Y")) | P5: =IF(O5="","",IF(O5<=11,"Infantil",IF(O5<=17,"Juvenil",IF(O5<=44,"Adulto","Baobá")))) | Q5: =IF(P5<>"Adulto","",IF(OR(L5="Marrom",L5="Marrom/Vermelha"),"A",IF(OR(L5="Roxa",L5="Roxa/Marrom"),"B",IF(OR(L5="Verde",L5="Verde/Roxa"),"C",IF(OR(L5="Azul",L5="Azul/Verde"),"D",IF(OR(L5="Laranja",L5="Laranja/Azul"),"E",IF(Y5="Sí","E","N/A"))))))) | R5: =IF(P5<>"Baobá","",IF(OR(L5="Laranja",L5="Laranja/Azul"),"Alumnos",IF(Y5="Sí","Alumnos","Graduados+"))) | S5: =IF(P5="","",IF(P5="Adulto",IF(OR(Q5="",Q5="N/A"),"⚠ Corda no compite Adulto",P5&"-"&Q5&" · "&M5),IF(P5="Baobá",IF(R5="","⚠ Sin clasificar Baobá",P5&"-"&R5&" · "&M5),IF(P5="Juvenil",IF(AND(OR(L5="Crua",L5="Crua/Amarela"),Y5<>"Sí"),"⚠ Juvenil necesita Amarela+",P5&" · "&M5),P5&" · "&M5)))) | U5: Sí | Y5: No | Z5: XS | AA5: 35 | AB5: Pagado | AD5: =IF(D5<>"","P"&TEXT(ROW()-4,"0000"),"")
A6: 2025-08-05 13:48:10 | D6: Francisco | E6: Monteiro | F6: Joaninha | G6: =IF(F6<>"",F6,IF(AND(D6="",E6=""),"",TRIM(D6&" "&E6))) | I6: +34 610 713 431 | J6: Bogotá-Colombia | K6: Mestre Bimba | L6: Marrom/Vermelha | M6: Masculino | N6: 37069 | O6: =IF(N6="","",DATEDIF(N6,TODAY(),"Y")) | P6: =IF(O6="","",IF(O6<=11,"Infantil",IF(O6<=17,"Juvenil",IF(O6<=44,"Adulto","Baobá")))) | Q6: =IF(P6<>"Adulto","",IF(OR(L6="Marrom",L6="Marrom/Vermelha"),"A",IF(OR(L6="Roxa",L6="Roxa/Marrom"),"B",IF(OR(L6="Verde",L6="Verde/Roxa"),"C",IF(OR(L6="Azul",L6="Azul/Verde"),"D",IF(OR(L6="Laranja",L6="Laranja/Azul"),"E",IF(Y6="Sí","E","N/A"))))))) | R6: =IF(P6<>"Baobá","",IF(OR(L6="Laranja",L6="Laranja/Azul"),"Alumnos",IF(Y6="Sí","Alumnos","Graduados+"))) | S6: =IF(P6="","",IF(P6="Adulto",IF(OR(Q6="",Q6="N/A"),"⚠ Corda no compite Adulto",P6&"-"&Q6&" · "&M6),IF(P6="Baobá",IF(R6="","⚠ Sin clasificar Baobá",P6&"-"&R6&" · "&M6),IF(P6="Juvenil",IF(AND(OR(L6="Crua",L6="Crua/Amarela"),Y6<>"Sí"),"⚠ Juvenil necesita Amarela+",P6&" · "&M6),P6&" · "&M6)))) | U6: Sí | Y6: No | Z6: S | AA6: 35 | AB6: Pagado | AD6: =IF(D6<>"","P"&TEXT(ROW()-4,"0000"),"")
A7: 2025-09-08 08:15:56 | D7: Fernando | E7: Rodrigues | F7: Jaguatirica | G7: =IF(F7<>"",F7,IF(AND(D7="",E7=""),"",TRIM(D7&" "&E7))) | I7: +34 620 849 597 | J7: Recife-Brasil | K7: Professor Tatu | L7: Marrom | M7: Masculino | N7: 36607 | O7: =IF(N7="","",DATEDIF(N7,TODAY(),"Y")) | P7: =IF(O7="","",IF(O7<=11,"Infantil",IF(O7<=17,"Juvenil",IF(O7<=44,"Adulto","Baobá")))) | Q7: =IF(P7<>"Adulto","",IF(OR(L7="Marrom",L7="Marrom/Vermelha"),"A",IF(OR(L7="Roxa",L7="Roxa/Marrom"),"B",IF(OR(L7="Verde",L7="Verde/Roxa"),"C",IF(OR(L7="Azul",L7="Azul/Verde"),"D",IF(OR(L7="Laranja",L7="Laranja/Azul"),"E",IF(Y7="Sí","E","N/A"))))))) | R7: =IF(P7<>"Baobá","",IF(OR(L7="Laranja",L7="Laranja/Azul"),"Alumnos",IF(Y7="Sí","Alumnos","Graduados+"))) | S7: =IF(P7="","",IF(P7="Adulto",IF(OR(Q7="",Q7="N/A"),"⚠ Corda no compite Adulto",P7&"-"&Q7&" · "&M7),IF(P7="Baobá",IF(R7="","⚠ Sin clasificar Baobá",P7&"-"&R7&" · "&M7),IF(P7="Juvenil",IF(AND(OR(L7="Crua",L7="Crua/Amarela"),Y7<>"Sí"),"⚠ Juvenil necesita Amarela+",P7&" · "&M7),P7&" · "&M7)))) | U7: Sí | Y7: No | Z7: M | AA7: 35 | AB7: Pagado | AD7: =IF(D7<>"","P"&TEXT(ROW()-4,"0000"),"")
A8: 2025-09-18 10:16:33 | D8: Nicolas | E8: Robert | F8: Coelho | G8: =IF(F8<>"",F8,IF(AND(D8="",E8=""),"",TRIM(D8&" "&E8))) | I8: +34 637 652 873 | J8: Bilbao-España | K8: Mestre Coruja | L8: Marrom/Vermelha | M8: Masculino | N8: 33929 | O8: =IF(N8="","",DATEDIF(N8,TODAY(),"Y")) | P8: =IF(O8="","",IF(O8<=11,"Infantil",IF(O8<=17,"Juvenil",IF(O8<=44,"Adulto","Baobá")))) | Q8: =IF(P8<>"Adulto","",IF(OR(L8="Marrom",L8="Marrom/Vermelha"),"A",IF(OR(L8="Roxa",L8="Roxa/Marrom"),"B",IF(OR(L8="Verde",L8="Verde/Roxa"),"C",IF(OR(L8="Azul",L8="Azul/Verde"),"D",IF(OR(L8="Laranja",L8="Laranja/Azul"),"E",IF(Y8="Sí","E","N/A"))))))) | R8: =IF(P8<>"Baobá","",IF(OR(L8="Laranja",L8="Laranja/Azul"),"Alumnos",IF(Y8="Sí","Alumnos","Graduados+"))) | S8: =IF(P8="","",IF(P8="Adulto",IF(OR(Q8="",Q8="N/A"),"⚠ Corda no compite Adulto",P8&"-"&Q8&" · "&M8),IF(P8="Baobá",IF(R8="","⚠ Sin clasificar Baobá",P8&"-"&R8&" · "&M8),IF(P8="Juvenil",IF(AND(OR(L8="Crua",L8="Crua/Amarela"),Y8<>"Sí"),"⚠ Juvenil necesita Amarela+",P8&" · "&M8),P8&" · "&M8)))) | U8: Sí | Y8: No | Z8: L | AA8: 35 | AB8: Pagado | AD8: =IF(D8<>"","P"&TEXT(ROW()-4,"0000"),"")
A9: 2025-09-15 22:33:28 | D9: Fábio | E9: Schmidt | F9: Veado | G9: =IF(F9<>"",F9,IF(AND(D9="",E9=""),"",TRIM(D9&" "&E9))) | I9: +34 638 165 446 | J9: Rio de Janeiro-Brasil | K9: Mestre Urso | L9: Marrom/Vermelha | M9: Masculino | N9: 31886 | O9: =IF(N9="","",DATEDIF(N9,TODAY(),"Y")) | P9: =IF(O9="","",IF(O9<=11,"Infantil",IF(O9<=17,"Juvenil",IF(O9<=44,"Adulto","Baobá")))) | Q9: =IF(P9<>"Adulto","",IF(OR(L9="Marrom",L9="Marrom/Vermelha"),"A",IF(OR(L9="Roxa",L9="Roxa/Marrom"),"B",IF(OR(L9="Verde",L9="Verde/Roxa"),"C",IF(OR(L9="Azul",L9="Azul/Verde"),"D",IF(OR(L9="Laranja",L9="Laranja/Azul"),"E",IF(Y9="Sí","E","N/A"))))))) | R9: =IF(P9<>"Baobá","",IF(OR(L9="Laranja",L9="Laranja/Azul"),"Alumnos",IF(Y9="Sí","Alumnos","Graduados+"))) | S9: =IF(P9="","",IF(P9="Adulto",IF(OR(Q9="",Q9="N/A"),"⚠ Corda no compite Adulto",P9&"-"&Q9&" · "&M9),IF(P9="Baobá",IF(R9="","⚠ Sin clasificar Baobá",P9&"-"&R9&" · "&M9),IF(P9="Juvenil",IF(AND(OR(L9="Crua",L9="Crua/Amarela"),Y9<>"Sí"),"⚠ Juvenil necesita Amarela+",P9&" · "&M9),P9&" · "&M9)))) | U9: Sí | Y9: No | Z9: XL | AA9: 35 | AB9: Pagado | AD9: =IF(D9<>"","P"&TEXT(ROW()-4,"0000"),"")
A10: 2025-08-01 09:45:40 | D10: Pedro | E10: Ruiz | F10: Gato-Preto | G10: =IF(F10<>"",F10,IF(AND(D10="",E10=""),"",TRIM(D10&" "&E10))) | I10: +34 618 132 980 | J10: Marseille-Francia | K10: Contra-Mestre Falcão | L10: Marrom/Vermelha | M10: Masculino | N10: 32242 | O10: =IF(N10="","",DATEDIF(N10,TODAY(),"Y")) | P10: =IF(O10="","",IF(O10<=11,"Infantil",IF(O10<=17,"Juvenil",IF(O10<=44,"Adulto","Baobá")))) | Q10: =IF(P10<>"Adulto","",IF(OR(L10="Marrom",L10="Marrom/Vermelha"),"A",IF(OR(L10="Roxa",L10="Roxa/Marrom"),"B",IF(OR(L10="Verde",L10="Verde/Roxa"),"C",IF(OR(L10="Azul",L10="Azul/Verde"),"D",IF(OR(L10="Laranja",L10="Laranja/Azul"),"E",IF(Y10="Sí","E","N/A"))))))) | R10: =IF(P10<>"Baobá","",IF(OR(L10="Laranja",L10="Laranja/Azul"),"Alumnos",IF(Y10="Sí","Alumnos","Graduados+"))) | S10: =IF(P10="","",IF(P10="Adulto",IF(OR(Q10="",Q10="N/A"),"⚠ Corda no compite Adulto",P10&"-"&Q10&" · "&M10),IF(P10="Baobá",IF(R10="","⚠ Sin clasificar Baobá",P10&"-"&R10&" · "&M10),IF(P10="Juvenil",IF(AND(OR(L10="Crua",L10="Crua/Amarela"),Y10<>"Sí"),"⚠ Juvenil necesita Amarela+",P10&" · "&M10),P10&" · "&M10)))) | U10: Sí | Y10: No | Z10: XXL | AA10: 35 | AB10: Pagado | AD10: =IF(D10<>"","P"&TEXT(ROW()-4,"0000"),"")
A11: 2025-10-16 11:34:08 | D11: Matteo | E11: Fernandes | F11: Coruja | G11: =IF(F11<>"",F11,IF(AND(D11="",E11=""),"",TRIM(D11&" "&E11))) | I11: +34 641 903 584 | J11: Milán-Italia | K11: Contra-Mestre Arara | L11: Marrom | M11: Masculino | N11: 36944 | O11: =IF(N11="","",DATEDIF(N11,TODAY(),"Y")) | P11: =IF(O11="","",IF(O11<=11,"Infantil",IF(O11<=17,"Juvenil",IF(O11<=44,"Adulto","Baobá")))) | Q11: =IF(P11<>"Adulto","",IF(OR(L11="Marrom",L11="Marrom/Vermelha"),"A",IF(OR(L11="Roxa",L11="Roxa/Marrom"),"B",IF(OR(L11="Verde",L11="Verde/Roxa"),"C",IF(OR(L11="Azul",L11="Azul/Verde"),"D",IF(OR(L11="Laranja",L11="Laranja/Azul"),"E",IF(Y11="Sí","E","N/A"))))))) | R11: =IF(P11<>"Baobá","",IF(OR(L11="Laranja",L11="Laranja/Azul"),"Alumnos",IF(Y11="Sí","Alumnos","Graduados+"))) | S11: =IF(P11="","",IF(P11="Adulto",IF(OR(Q11="",Q11="N/A"),"⚠ Corda no compite Adulto",P11&"-"&Q11&" · "&M11),IF(P11="Baobá",IF(R11="","⚠ Sin clasificar Baobá",P11&"-"&R11&" · "&M11),IF(P11="Juvenil",IF(AND(OR(L11="Crua",L11="Crua/Amarela"),Y11<>"Sí"),"⚠ Juvenil necesita Amarela+",P11&" · "&M11),P11&" · "&M11)))) | U11: Sí | Y11: No | Z11: XS | AA11: 35 | AB11: Pagado | AD11: =IF(D11<>"","P"&TEXT(ROW()-4,"0000"),"")
A12: 2025-09-12 14:26:29 | D12: Matteo | E12: Ferreira | F12: Boto | G12: =IF(F12<>"",F12,IF(AND(D12="",E12=""),"",TRIM(D12&" "&E12))) | I12: +34 696 769 761 | J12: Curitiba-Brasil | K12: Mestre Pastinha | L12: Marrom/Vermelha | M12: Masculino | N12: 33949 | O12: =IF(N12="","",DATEDIF(N12,TODAY(),"Y")) | P12: =IF(O12="","",IF(O12<=11,"Infantil",IF(O12<=17,"Juvenil",IF(O12<=44,"Adulto","Baobá")))) | Q12: =IF(P12<>"Adulto","",IF(OR(L12="Marrom",L12="Marrom/Vermelha"),"A",IF(OR(L12="Roxa",L12="Roxa/Marrom"),"B",IF(OR(L12="Verde",L12="Verde/Roxa"),"C",IF(OR(L12="Azul",L12="Azul/Verde"),"D",IF(OR(L12="Laranja",L12="Laranja/Azul"),"E",IF(Y12="Sí","E","N/A"))))))) | R12: =IF(P12<>"Baobá","",IF(OR(L12="Laranja",L12="Laranja/Azul"),"Alumnos",IF(Y12="Sí","Alumnos","Graduados+"))) | S12: =IF(P12="","",IF(P12="Adulto",IF(OR(Q12="",Q12="N/A"),"⚠ Corda no compite Adulto",P12&"-"&Q12&" · "&M12),IF(P12="Baobá",IF(R12="","⚠ Sin clasificar Baobá",P12&"-"&R12&" · "&M12),IF(P12="Juvenil",IF(AND(OR(L12="Crua",L12="Crua/Amarela"),Y12<>"Sí"),"⚠ Juvenil necesita Amarela+",P12&" · "&M12),P12&" · "&M12)))) | U12: Sí | Y12: No | Z12: S | AA12: 35 | AB12: Pagado | AD12: =IF(D12<>"","P"&TEXT(ROW()-4,"0000"),"")
A13: 2025-08-08 11:12:34 | D13: Thiago | E13: Barbosa | F13: Gato | G13: =IF(F13<>"",F13,IF(AND(D13="",E13=""),"",TRIM(D13&" "&E13))) | I13: +34 664 287 385 | J13: Montevideo-Uruguay | K13: Mestre Onça | L13: Marrom | M13: Masculino | N13: 37494 | O13: =IF(N13="","",DATEDIF(N13,TODAY(),"Y")) | P13: =IF(O13="","",IF(O13<=11,"Infantil",IF(O13<=17,"Juvenil",IF(O13<=44,"Adulto","Baobá")))) | Q13: =IF(P13<>"Adulto","",IF(OR(L13="Marrom",L13="Marrom/Vermelha"),"A",IF(OR(L13="Roxa",L13="Roxa/Marrom"),"B",IF(OR(L13="Verde",L13="Verde/Roxa"),"C",IF(OR(L13="Azul",L13="Azul/Verde"),"D",IF(OR(L13="Laranja",L13="Laranja/Azul"),"E",IF(Y13="Sí","E","N/A"))))))) | R13: =IF(P13<>"Baobá","",IF(OR(L13="Laranja",L13="Laranja/Azul"),"Alumnos",IF(Y13="Sí","Alumnos","Graduados+"))) | S13: =IF(P13="","",IF(P13="Adulto",IF(OR(Q13="",Q13="N/A"),"⚠ Corda no compite Adulto",P13&"-"&Q13&" · "&M13),IF(P13="Baobá",IF(R13="","⚠ Sin clasificar Baobá",P13&"-"&R13&" · "&M13),IF(P13="Juvenil",IF(AND(OR(L13="Crua",L13="Crua/Amarela"),Y13<>"Sí"),"⚠ Juvenil necesita Amarela+",P13&" · "&M13),P13&" · "&M13)))) | U13: Sí | Y13: No | Z13: M | AA13: 35 | AB13: Pagado | AD13: =IF(D13<>"","P"&TEXT(ROW()-4,"0000"),"")
A14: 2025-10-04 08:41:34 | D14: Carlos | E14: Martins | F14: Salamandra | G14: =IF(F14<>"",F14,IF(AND(D14="",E14=""),"",TRIM(D14&" "&E14))) | I14: +34 640 270 516 | J14: Bogotá-Colombia | K14: Mestre Tartaruga | L14: Marrom | M14: Masculino | N14: 35978 | O14: =IF(N14="","",DATEDIF(N14,TODAY(),"Y")) | P14: =IF(O14="","",IF(O14<=11,"Infantil",IF(O14<=17,"Juvenil",IF(O14<=44,"Adulto","Baobá")))) | Q14: =IF(P14<>"Adulto","",IF(OR(L14="Marrom",L14="Marrom/Vermelha"),"A",IF(OR(L14="Roxa",L14="Roxa/Marrom"),"B",IF(OR(L14="Verde",L14="Verde/Roxa"),"C",IF(OR(L14="Azul",L14="Azul/Verde"),"D",IF(OR(L14="Laranja",L14="Laranja/Azul"),"E",IF(Y14="Sí","E","N/A"))))))) | R14: =IF(P14<>"Baobá","",IF(OR(L14="Laranja",L14="Laranja/Azul"),"Alumnos",IF(Y14="Sí","Alumnos","Graduados+"))) | S14: =IF(P14="","",IF(P14="Adulto",IF(OR(Q14="",Q14="N/A"),"⚠ Corda no compite Adulto",P14&"-"&Q14&" · "&M14),IF(P14="Baobá",IF(R14="","⚠ Sin clasificar Baobá",P14&"-"&R14&" · "&M14),IF(P14="Juvenil",IF(AND(OR(L14="Crua",L14="Crua/Amarela"),Y14<>"Sí"),"⚠ Juvenil necesita Amarela+",P14&" · "&M14),P14&" · "&M14)))) | U14: Sí | Y14: No | Z14: L | AA14: 35 | AB14: Pagado | AD14: =IF(D14<>"","P"&TEXT(ROW()-4,"0000"),"")
A15: 2025-08-13 08:24:16 | D15: Caio | E15: Wagner | F15: Cágado | G15: =IF(F15<>"",F15,IF(AND(D15="",E15=""),"",TRIM(D15&" "&E15))) | I15: +34 664 813 848 | J15: Bogotá-Colombia | K15: Mestre Cobra | L15: Marrom/Vermelha | M15: Masculino | N15: 35922 | O15: =IF(N15="","",DATEDIF(N15,TODAY(),"Y")) | P15: =IF(O15="","",IF(O15<=11,"Infantil",IF(O15<=17,"Juvenil",IF(O15<=44,"Adulto","Baobá")))) | Q15: =IF(P15<>"Adulto","",IF(OR(L15="Marrom",L15="Marrom/Vermelha"),"A",IF(OR(L15="Roxa",L15="Roxa/Marrom"),"B",IF(OR(L15="Verde",L15="Verde/Roxa"),"C",IF(OR(L15="Azul",L15="Azul/Verde"),"D",IF(OR(L15="Laranja",L15="Laranja/Azul"),"E",IF(Y15="Sí","E","N/A"))))))) | R15: =IF(P15<>"Baobá","",IF(OR(L15="Laranja",L15="Laranja/Azul"),"Alumnos",IF(Y15="Sí","Alumnos","Graduados+"))) | S15: =IF(P15="","",IF(P15="Adulto",IF(OR(Q15="",Q15="N/A"),"⚠ Corda no compite Adulto",P15&"-"&Q15&" · "&M15),IF(P15="Baobá",IF(R15="","⚠ Sin clasificar Baobá",P15&"-"&R15&" · "&M15),IF(P15="Juvenil",IF(AND(OR(L15="Crua",L15="Crua/Amarela"),Y15<>"Sí"),"⚠ Juvenil necesita Amarela+",P15&" · "&M15),P15&" · "&M15)))) | U15: Sí | Y15: No | Z15: XL | AA15: 35 | AB15: Pagado | AD15: =IF(D15<>"","P"&TEXT(ROW()-4,"0000"),"")
A16: 2025-08-19 19:34:03 | D16: Luca | E16: Rossi | F16: Tartaruga | G16: =IF(F16<>"",F16,IF(AND(D16="",E16=""),"",TRIM(D16&" "&E16))) | I16: +34 617 151 698 | J16: Santiago-Chile | K16: Contra-Mestre Pomba | L16: Marrom/Vermelha | M16: Masculino | N16: 32204 | O16: =IF(N16="","",DATEDIF(N16,TODAY(),"Y")) | P16: =IF(O16="","",IF(O16<=11,"Infantil",IF(O16<=17,"Juvenil",IF(O16<=44,"Adulto","Baobá")))) | Q16: =IF(P16<>"Adulto","",IF(OR(L16="Marrom",L16="Marrom/Vermelha"),"A",IF(OR(L16="Roxa",L16="Roxa/Marrom"),"B",IF(OR(L16="Verde",L16="Verde/Roxa"),"C",IF(OR(L16="Azul",L16="Azul/Verde"),"D",IF(OR(L16="Laranja",L16="Laranja/Azul"),"E",IF(Y16="Sí","E","N/A"))))))) | R16: =IF(P16<>"Baobá","",IF(OR(L16="Laranja",L16="Laranja/Azul"),"Alumnos",IF(Y16="Sí","Alumnos","Graduados+"))) | S16: =IF(P16="","",IF(P16="Adulto",IF(OR(Q16="",Q16="N/A"),"⚠ Corda no compite Adulto",P16&"-"&Q16&" · "&M16),IF(P16="Baobá",IF(R16="","⚠ Sin clasificar Baobá",P16&"-"&R16&" · "&M16),IF(P16="Juvenil",IF(AND(OR(L16="Crua",L16="Crua/Amarela"),Y16<>"Sí"),"⚠ Juvenil necesita Amarela+",P16&" · "&M16),P16&" · "&M16)))) | U16: Sí | Y16: No | Z16: XXL | AA16: 35 | AB16: Pagado | AD16: =IF(D16<>"","P"&TEXT(ROW()-4,"0000"),"")
... A292: 2025-10-17 13:27:56 | D292: Claudia | E292: Barbosa | F292: Urubu-Rei | G292: =IF(F292<>"",F292,IF(AND(D292="",E292=""),"",TRIM(D292&" "&E292))) | I292: +34 653 601 467 | J292: Bilbao-España | K292: Professor Gavião | L292: Laranja | M292: Femenino | N292: 33611 | O292: =IF(N292="","",DATEDIF(N292,TODAY(),"Y")) | P292: =IF(O292="","",IF(O292<=11,"Infantil",IF(O292<=17,"Juvenil",IF(O292<=44,"Adulto","Baobá")))) | Q292: =IF(P292<>"Adulto","",IF(OR(L292="Marrom",L292="Marrom/Vermelha"),"A",IF(OR(L292="Roxa",L292="Roxa/Marrom"),"B",IF(OR(L292="Verde",L292="Verde/Roxa"),"C",IF(OR(L292="Azul",L292="Azul/Verde"),"D",IF(OR(L292="Laranja",L292="Laranja/Azul"),"E",IF(Y292="Sí","E","N/A"))))))) | R292: =IF(P292<>"Baobá","",IF(OR(L292="Laranja",L292="Laranja/Azul"),"Alumnos",IF(Y292="Sí","Alumnos","Graduados+"))) | S292: =IF(P292="","",IF(P292="Adulto",IF(OR(Q292="",Q292="N/A"),"⚠ Corda no compite Adulto",P292&"-"&Q292&" · "&M292),IF(P292="Baobá",IF(R292="","⚠ Sin clasificar Baobá",P292&"-"&R292&" · "&M292),IF(P292="Juvenil",IF(AND(OR(L292="Crua",L292="Crua/Amarela"),Y292<>"Sí"),"⚠ Juvenil necesita Amarela+",P292&" · "&M292),P292&" · "&M292)))) | U292: Sí | Y292: No | Z292: S | AA292: 35 | AB292: Pagado | AD292: =IF(D292<>"","P"&TEXT(ROW()-4,"0000"),"")

Sheet PARTICIPANTES
A1: PARTICIPANTES · Tabla normalizada (lectura)
A4: orden | B4: id_participante | C4: id_llave | D4: categoria_final | E4: nombre_mostrar | F4: corda | G4: orden_corda | H4: genero | I4: edad | J4: ciudad_pais | K4: profesor | L4: compite_jogo | M4: compite_festival | N4: categoria_festival | O4: miembros_grupo | P4: estado_pago | Q4: activo | R4: rank_score
A5: =IF(INSCRITOS_FORM!D5<>"",ROW()-4,"") | B5: =INSCRITOS_FORM!AD5 | C5: =INSCRITOS_FORM!T5 | D5: =INSCRITOS_FORM!S5 | E5: =INSCRITOS_FORM!G5 | F5: =INSCRITOS_FORM!L5 | G5: {=IFERROR(INDEX(CONFIG!$A$22:$A$35,MATCH(F5,CONFIG!$B$22:$B$35,0)),0)} | H5: =INSCRITOS_FORM!M5 | I5: =INSCRITOS_FORM!O5 | J5: =INSCRITOS_FORM!J5 | K5: =INSCRITOS_FORM!K5 | L5: =INSCRITOS_FORM!U5 | M5: =INSCRITOS_FORM!V5 | N5: =INSCRITOS_FORM!W5 | O5: =INSCRITOS_FORM!X5 | P5: =INSCRITOS_FORM!AB5 | Q5: =IF(B5="","",IF(AND(OR(P5="Pagado",P5="Beca",P5="Invitado"),OR(L5="Sí",M5="Sí")),"Sí","No")) | R5: =IF(AND(C5=TORNEO_ACTIVO!$B$3,Q5="Sí"),G5*10000-A5,-1)
A6: =IF(INSCRITOS_FORM!D6<>"",ROW()-4,"") | B6: =INSCRITOS_FORM!AD6 | C6: =INSCRITOS_FORM!T6 | D6: =INSCRITOS_FORM!S6 | E6: =INSCRITOS_FORM!G6 | F6: =INSCRITOS_FORM!L6 | G6: {=IFERROR(INDEX(CONFIG!$A$22:$A$35,MATCH(F6,CONFIG!$B$22:$B$35,0)),0)} | H6: =INSCRITOS_FORM!M6 | I6: =INSCRITOS_FORM!O6 | J6: =INSCRITOS_FORM!J6 | K6: =INSCRITOS_FORM!K6 | L6: =INSCRITOS_FORM!U6 | M6: =INSCRITOS_FORM!V6 | N6: =INSCRITOS_FORM!W6 | O6: =INSCRITOS_FORM!X6 | P6: =INSCRITOS_FORM!AB6 | Q6: =IF(B6="","",IF(AND(OR(P6="Pagado",P6="Beca",P6="Invitado"),OR(L6="Sí",M6="Sí")),"Sí","No")) | R6: =IF(AND(C6=TORNEO_ACTIVO!$B$3,Q6="Sí"),G6*10000-A6,-1)
A7: =IF(INSCRITOS_FORM!D7<>"",ROW()-4,"") | B7: =INSCRITOS_FORM!AD7 | C7: =INSCRITOS_FORM!T7 | D7: =INSCRITOS_FORM!S7 | E7: =INSCRITOS_FORM!G7 | F7: =INSCRITOS_FORM!L7 | G7: {=IFERROR(INDEX(CONFIG!$A$22:$A$35,MATCH(F7,CONFIG!$B$22:$B$35,0)),0)} | H7: =INSCRITOS_FORM!M7 | I7: =INSCRITOS_FORM!O7 | J7: =INSCRITOS_FORM!J7 | K7: =INSCRITOS_FORM!K7 | L7: =INSCRITOS_FORM!U7 | M7: =INSCRITOS_FORM!V7 | N7: =INSCRITOS_FORM!W7 | O7: =INSCRITOS_FORM!X7 | P7: =INSCRITOS_FORM!AB7 | Q7: =IF(B7="","",IF(AND(OR(P7="Pagado",P7="Beca",P7="Invitado"),OR(L7="Sí",M7="Sí")),"Sí","No")) | R7: =IF(AND(C7=TORNEO_ACTIVO!$B$3,Q7="Sí"),G7*10000-A7,-1)
A8: =IF(INSCRITOS_FORM!D8<>"",ROW()-4,"") | B8: =INSCRITOS_FORM!AD8 | C8: =INSCRITOS_FORM!T8 | D8: =INSCRITOS_FORM!S8 | E8: =INSCRITOS_FORM!G8 | F8: =INSCRITOS_FORM!L8 | G8: {=IFERROR(INDEX(CONFIG!$A$22:$A$35,MATCH(F8,CONFIG!$B$22:$B$35,0)),0)} | H8: =INSCRITOS_FORM!M8 | I8: =INSCRITOS_FORM!O8 | J8: =INSCRITOS_FORM!J8 | K8: =INSCRITOS_FORM!K8 | L8: =INSCRITOS_FORM!U8 | M8: =INSCRITOS_FORM!V8 | N8: =INSCRITOS_FORM!W8 | O8: =INSCRITOS_FORM!X8 | P8: =INSCRITOS_FORM!AB8 | Q8: =IF(B8="","",IF(AND(OR(P8="Pagado",P8="Beca",P8="Invitado"),OR(L8="Sí",M8="Sí")),"Sí","No")) | R8: =IF(AND(C8=TORNEO_ACTIVO!$B$3,Q8="Sí"),G8*10000-A8,-1)
A9: =IF(INSCRITOS_FORM!D9<>"",ROW()-4,"") | B9: =INSCRITOS_FORM!AD9 | C9: =INSCRITOS_FORM!T9 | D9: =INSCRITOS_FORM!S9 | E9: =INSCRITOS_FORM!G9 | F9: =INSCRITOS_FORM!L9 | G9: {=IFERROR(INDEX(CONFIG!$A$22:$A$35,MATCH(F9,CONFIG!$B$22:$B$35,0)),0)} | H9: =INSCRITOS_FORM!M9 | I9: =INSCRITOS_FORM!O9 | J9: =INSCRITOS_FORM!J9 | K9: =INSCRITOS_FORM!K9 | L9: =INSCRITOS_FORM!U9 | M9: =INSCRITOS_FORM!V9 | N9: =INSCRITOS_FORM!W9 | O9: =INSCRITOS_FORM!X9 | P9: =INSCRITOS_FORM!AB9 | Q9: =IF(B9="","",IF(AND(OR(P9="Pagado",P9="Beca",P9="Invitado"),OR(L9="Sí",M9="Sí")),"Sí","No")) | R9: =IF(AND(C9=TORNEO_ACTIVO!$B$3,Q9="Sí"),G9*10000-A9,-1)
A10: =IF(INSCRITOS_FORM!D10<>"",ROW()-4,"") | B10: =INSCRITOS_FORM!AD10 | C10: =INSCRITOS_FORM!T10 | D10: =INSCRITOS_FORM!S10 | E10: =INSCRITOS_FORM!G10 | F10: =INSCRITOS_FORM!L10 | G10: {=IFERROR(INDEX(CONFIG!$A$22:$A$35,MATCH(F10,CONFIG!$B$22:$B$35,0)),0)} | H10: =INSCRITOS_FORM!M10 | I10: =INSCRITOS_FORM!O10 | J10: =INSCRITOS_FORM!J10 | K10: =INSCRITOS_FORM!K10 | L10: =INSCRITOS_FORM!U10 | M10: =INSCRITOS_FORM!V10 | N10: =INSCRITOS_FORM!W10 | O10: =INSCRITOS_FORM!X10 | P10: =INSCRITOS_FORM!AB10 | Q10: =IF(B10="","",IF(AND(OR(P10="Pagado",P10="Beca",P10="Invitado"),OR(L10="Sí",M10="Sí")),"Sí","No")) | R10: =IF(AND(C10=TORNEO_ACTIVO!$B$3,Q10="Sí"),G10*10000-A10,-1)
A11: =IF(INSCRITOS_FORM!D11<>"",ROW()-4,"") | B11: =INSCRITOS_FORM!AD11 | C11: =INSCRITOS_FORM!T11 | D11: =INSCRITOS_FORM!S11 | E11: =INSCRITOS_FORM!G11 | F11: =INSCRITOS_FORM!L11 | G11: {=IFERROR(INDEX(CONFIG!$A$22:$A$35,MATCH(F11,CONFIG!$B$22:$B$35,0)),0)} | H11: =INSCRITOS_FORM!M11 | I11: =INSCRITOS_FORM!O11 | J11: =INSCRITOS_FORM!J11 | K11: =INSCRITOS_FORM!K11 | L11: =INSCRITOS_FORM!U11 | M11: =INSCRITOS_FORM!V11 | N11: =INSCRITOS_FORM!W11 | O11: =INSCRITOS_FORM!X11 | P11: =INSCRITOS_FORM!AB11 | Q11: =IF(B11="","",IF(AND(OR(P11="Pagado",P11="Beca",P11="Invitado"),OR(L11="Sí",M11="Sí")),"Sí","No")) | R11: =IF(AND(C11=TORNEO_ACTIVO!$B$3,Q11="Sí"),G11*10000-A11,-1)
A12: =IF(INSCRITOS_FORM!D12<>"",ROW()-4,"") | B12: =INSCRITOS_FORM!AD12 | C12: =INSCRITOS_FORM!T12 | D12: =INSCRITOS_FORM!S12 | E12: =INSCRITOS_FORM!G12 | F12: =INSCRITOS_FORM!L12 | G12: {=IFERROR(INDEX(CONFIG!$A$22:$A$35,MATCH(F12,CONFIG!$B$22:$B$35,0)),0)} | H12: =INSCRITOS_FORM!M12 | I12: =INSCRITOS_FORM!O12 | J12: =INSCRITOS_FORM!J12 | K12: =INSCRITOS_FORM!K12 | L12: =INSCRITOS_FORM!U12 | M12: =INSCRITOS_FORM!V12 | N12: =INSCRITOS_FORM!W12 | O12: =INSCRITOS_FORM!X12 | P12: =INSCRITOS_FORM!AB12 | Q12: =IF(B12="","",IF(AND(OR(P12="Pagado",P12="Beca",P12="Invitado"),OR(L12="Sí",M12="Sí")),"Sí","No")) | R12: =IF(AND(C12=TORNEO_ACTIVO!$B$3,Q12="Sí"),G12*10000-A12,-1)
A13: =IF(INSCRITOS_FORM!D13<>"",ROW()-4,"") | B13: =INSCRITOS_FORM!AD13 | C13: =INSCRITOS_FORM!T13 | D13: =INSCRITOS_FORM!S13 | E13: =INSCRITOS_FORM!G13 | F13: =INSCRITOS_FORM!L13 | G13: {=IFERROR(INDEX(CONFIG!$A$22:$A$35,MATCH(F13,CONFIG!$B$22:$B$35,0)),0)} | H13: =INSCRITOS_FORM!M13 | I13: =INSCRITOS_FORM!O13 | J13: =INSCRITOS_FORM!J13 | K13: =INSCRITOS_FORM!K13 | L13: =INSCRITOS_FORM!U13 | M13: =INSCRITOS_FORM!V13 | N13: =INSCRITOS_FORM!W13 | O13: =INSCRITOS_FORM!X13 | P13: =INSCRITOS_FORM!AB13 | Q13: =IF(B13="","",IF(AND(OR(P13="Pagado",P13="Beca",P13="Invitado"),OR(L13="Sí",M13="Sí")),"Sí","No")) | R13: =IF(AND(C13=TORNEO_ACTIVO!$B$3,Q13="Sí"),G13*10000-A13,-1)
A14: =IF(INSCRITOS_FORM!D14<>"",ROW()-4,"") | B14: =INSCRITOS_FORM!AD14 | C14: =INSCRITOS_FORM!T14 | D14: =INSCRITOS_FORM!S14 | E14: =INSCRITOS_FORM!G14 | F14: =INSCRITOS_FORM!L14 | G14: {=IFERROR(INDEX(CONFIG!$A$22:$A$35,MATCH(F14,CONFIG!$B$22:$B$35,0)),0)} | H14: =INSCRITOS_FORM!M14 | I14: =INSCRITOS_FORM!O14 | J14: =INSCRITOS_FORM!J14 | K14: =INSCRITOS_FORM!K14 | L14: =INSCRITOS_FORM!U14 | M14: =INSCRITOS_FORM!V14 | N14: =INSCRITOS_FORM!W14 | O14: =INSCRITOS_FORM!X14 | P14: =INSCRITOS_FORM!AB14 | Q14: =IF(B14="","",IF(AND(OR(P14="Pagado",P14="Beca",P14="Invitado"),OR(L14="Sí",M14="Sí")),"Sí","No")) | R14: =IF(AND(C14=TORNEO_ACTIVO!$B$3,Q14="Sí"),G14*10000-A14,-1)
A15: =IF(INSCRITOS_FORM!D15<>"",ROW()-4,"") | B15: =INSCRITOS_FORM!AD15 | C15: =INSCRITOS_FORM!T15 | D15: =INSCRITOS_FORM!S15 | E15: =INSCRITOS_FORM!G15 | F15: =INSCRITOS_FORM!L15 | G15: {=IFERROR(INDEX(CONFIG!$A$22:$A$35,MATCH(F15,CONFIG!$B$22:$B$35,0)),0)} | H15: =INSCRITOS_FORM!M15 | I15: =INSCRITOS_FORM!O15 | J15: =INSCRITOS_FORM!J15 | K15: =INSCRITOS_FORM!K15 | L15: =INSCRITOS_FORM!U15 | M15: =INSCRITOS_FORM!V15 | N15: =INSCRITOS_FORM!W15 | O15: =INSCRITOS_FORM!X15 | P15: =INSCRITOS_FORM!AB15 | Q15: =IF(B15="","",IF(AND(OR(P15="Pagado",P15="Beca",P15="Invitado"),OR(L15="Sí",M15="Sí")),"Sí","No")) | R15: =IF(AND(C15=TORNEO_ACTIVO!$B$3,Q15="Sí"),G15*10000-A15,-1)
A16: =IF(INSCRITOS_FORM!D16<>"",ROW()-4,"") | B16: =INSCRITOS_FORM!AD16 | C16: =INSCRITOS_FORM!T16 | D16: =INSCRITOS_FORM!S16 | E16: =INSCRITOS_FORM!G16 | F16: =INSCRITOS_FORM!L16 | G16: {=IFERROR(INDEX(CONFIG!$A$22:$A$35,MATCH(F16,CONFIG!$B$22:$B$35,0)),0)} | H16: =INSCRITOS_FORM!M16 | I16: =INSCRITOS_FORM!O16 | J16: =INSCRITOS_FORM!J16 | K16: =INSCRITOS_FORM!K16 | L16: =INSCRITOS_FORM!U16 | M16: =INSCRITOS_FORM!V16 | N16: =INSCRITOS_FORM!W16 | O16: =INSCRITOS_FORM!X16 | P16: =INSCRITOS_FORM!AB16 | Q16: =IF(B16="","",IF(AND(OR(P16="Pagado",P16="Beca",P16="Invitado"),OR(L16="Sí",M16="Sí")),"Sí","No")) | R16: =IF(AND(C16=TORNEO_ACTIVO!$B$3,Q16="Sí"),G16*10000-A16,-1)
... A504: =IF(INSCRITOS_FORM!D504<>"",ROW()-4,"") | B504: =INSCRITOS_FORM!AD504 | C504: =INSCRITOS_FORM!T504 | D504: =INSCRITOS_FORM!S504 | E504: =INSCRITOS_FORM!G504 | F504: =INSCRITOS_FORM!L504 | G504: {=IFERROR(INDEX(CONFIG!$A$22:$A$35,MATCH(F504,CONFIG!$B$22:$B$35,0)),0)} | H504: =INSCRITOS_FORM!M504 | I504: =INSCRITOS_FORM!O504 | J504: =INSCRITOS_FORM!J504 | K504: =INSCRITOS_FORM!K504 | L504: =INSCRITOS_FORM!U504 | M504: =INSCRITOS_FORM!V504 | N504: =INSCRITOS_FORM!W504 | O504: =INSCRITOS_FORM!X504 | P504: =INSCRITOS_FORM!AB504 | Q504: =IF(B504="","",IF(AND(OR(P504="Pagado",P504="Beca",P504="Invitado"),OR(L504="Sí",M504="Sí")),"Sí","No")) | R504: =IF(AND(C504=TORNEO_ACTIVO!$B$3,Q504="Sí"),G504*10000-A504,-1)

Sheet LLAVES_INDEX
A1: LLAVES_INDEX · Catálogo de las 22 llaves
A4: ID | B4: Categoría | C4: Tipo | D4: Inscritos | E4: Activos | F4: Tamaño llave | G4: Ronda inicial | H4: BYEs | I4: Estado | J4: Mesa | K4: Observaciones
A5: L01 | B5: Infantil · Masculino | C5: Jogo | D5: =COUNTIFS(PARTICIPANTES!$C$5:$C$504,$A5,PARTICIPANTES!$L$5:$L$504,"Sí") | E5: =COUNTIFS(PARTICIPANTES!$C$5:$C$504,$A5,PARTICIPANTES!$L$5:$L$504,"Sí",PARTICIPANTES!$Q$5:$Q$504,"Sí") | F5: =IF(E5<=1,"-",IF(E5<=4,4,IF(E5<=8,8,IF(E5<=16,16,32)))) | G5: =IF(F5=4,"Final",IF(F5=8,"Semifinal",IF(F5=16,"Octavas",IF(F5=32,"Eliminatoria","-")))) | H5: =IF(OR(F5="-",E5=0),0,F5-E5) | I5: =IF(E5=0,"⚪ Sin inscritos",IF(E5=1,"⚠ Solo 1 inscrito",IF(E5<4,"🟡 Pocos inscritos","🟢 Lista")))
A6: L02 | B6: Infantil · Femenino | C6: Jogo | D6: =COUNTIFS(PARTICIPANTES!$C$5:$C$504,$A6,PARTICIPANTES!$L$5:$L$504,"Sí") | E6: =COUNTIFS(PARTICIPANTES!$C$5:$C$504,$A6,PARTICIPANTES!$L$5:$L$504,"Sí",PARTICIPANTES!$Q$5:$Q$504,"Sí") | F6: =IF(E6<=1,"-",IF(E6<=4,4,IF(E6<=8,8,IF(E6<=16,16,32)))) | G6: =IF(F6=4,"Final",IF(F6=8,"Semifinal",IF(F6=16,"Octavas",IF(F6=32,"Eliminatoria","-")))) | H6: =IF(OR(F6="-",E6=0),0,F6-E6) | I6: =IF(E6=0,"⚪ Sin inscritos",IF(E6=1,"⚠ Solo 1 inscrito",IF(E6<4,"🟡 Pocos inscritos","🟢 Lista")))
A7: L03 | B7: Juvenil · Masculino | C7: Jogo | D7: =COUNTIFS(PARTICIPANTES!$C$5:$C$504,$A7,PARTICIPANTES!$L$5:$L$504,"Sí") | E7: =COUNTIFS(PARTICIPANTES!$C$5:$C$504,$A7,PARTICIPANTES!$L$5:$L$504,"Sí",PARTICIPANTES!$Q$5:$Q$504,"Sí") | F7: =IF(E7<=1,"-",IF(E7<=4,4,IF(E7<=8,8,IF(E7<=16,16,32)))) | G7: =IF(F7=4,"Final",IF(F7=8,"Semifinal",IF(F7=16,"Octavas",IF(F7=32,"Eliminatoria","-")))) | H7: =IF(OR(F7="-",E7=0),0,F7-E7) | I7: =IF(E7=0,"⚪ Sin inscritos",IF(E7=1,"⚠ Solo 1 inscrito",IF(E7<4,"🟡 Pocos inscritos","🟢 Lista")))
A8: L04 | B8: Juvenil · Femenino | C8: Jogo | D8: =COUNTIFS(PARTICIPANTES!$C$5:$C$504,$A8,PARTICIPANTES!$L$5:$L$504,"Sí") | E8: =COUNTIFS(PARTICIPANTES!$C$5:$C$504,$A8,PARTICIPANTES!$L$5:$L$504,"Sí",PARTICIPANTES!$Q$5:$Q$504,"Sí") | F8: =IF(E8<=1,"-",IF(E8<=4,4,IF(E8<=8,8,IF(E8<=16,16,32)))) | G8: =IF(F8=4,"Final",IF(F8=8,"Semifinal",IF(F8=16,"Octavas",IF(F8=32,"Eliminatoria","-")))) | H8: =IF(OR(F8="-",E8=0),0,F8-E8) | I8: =IF(E8=0,"⚪ Sin inscritos",IF(E8=1,"⚠ Solo 1 inscrito",IF(E8<4,"🟡 Pocos inscritos","🟢 Lista")))
A9: L05 | B9: Adulto-A · Masculino | C9: Jogo | D9: =COUNTIFS(PARTICIPANTES!$C$5:$C$504,$A9,PARTICIPANTES!$L$5:$L$504,"Sí") | E9: =COUNTIFS(PARTICIPANTES!$C$5:$C$504,$A9,PARTICIPANTES!$L$5:$L$504,"Sí",PARTICIPANTES!$Q$5:$Q$504,"Sí") | F9: =IF(E9<=1,"-",IF(E9<=4,4,IF(E9<=8,8,IF(E9<=16,16,32)))) | G9: =IF(F9=4,"Final",IF(F9=8,"Semifinal",IF(F9=16,"Octavas",IF(F9=32,"Eliminatoria","-")))) | H9: =IF(OR(F9="-",E9=0),0,F9-E9) | I9: =IF(E9=0,"⚪ Sin inscritos",IF(E9=1,"⚠ Solo 1 inscrito",IF(E9<4,"🟡 Pocos inscritos","🟢 Lista")))
A10: L06 | B10: Adulto-A · Femenino | C10: Jogo | D10: =COUNTIFS(PARTICIPANTES!$C$5:$C$504,$A10,PARTICIPANTES!$L$5:$L$504,"Sí") | E10: =COUNTIFS(PARTICIPANTES!$C$5:$C$504,$A10,PARTICIPANTES!$L$5:$L$504,"Sí",PARTICIPANTES!$Q$5:$Q$504,"Sí") | F10: =IF(E10<=1,"-",IF(E10<=4,4,IF(E10<=8,8,IF(E10<=16,16,32)))) | G10: =IF(F10=4,"Final",IF(F10=8,"Semifinal",IF(F10=16,"Octavas",IF(F10=32,"Eliminatoria","-")))) | H10: =IF(OR(F10="-",E10=0),0,F10-E10) | I10: =IF(E10=0,"⚪ Sin inscritos",IF(E10=1,"⚠ Solo 1 inscrito",IF(E10<4,"🟡 Pocos inscritos","🟢 Lista")))
A11: L07 | B11: Adulto-B · Masculino | C11: Jogo | D11: =COUNTIFS(PARTICIPANTES!$C$5:$C$504,$A11,PARTICIPANTES!$L$5:$L$504,"Sí") | E11: =COUNTIFS(PARTICIPANTES!$C$5:$C$504,$A11,PARTICIPANTES!$L$5:$L$504,"Sí",PARTICIPANTES!$Q$5:$Q$504,"Sí") | F11: =IF(E11<=1,"-",IF(E11<=4,4,IF(E11<=8,8,IF(E11<=16,16,32)))) | G11: =IF(F11=4,"Final",IF(F11=8,"Semifinal",IF(F11=16,"Octavas",IF(F11=32,"Eliminatoria","-")))) | H11: =IF(OR(F11="-",E11=0),0,F11-E11) | I11: =IF(E11=0,"⚪ Sin inscritos",IF(E11=1,"⚠ Solo 1 inscrito",IF(E11<4,"🟡 Pocos inscritos","🟢 Lista")))
A12: L08 | B12: Adulto-B · Femenino | C12: Jogo | D12: =COUNTIFS(PARTICIPANTES!$C$5:$C$504,$A12,PARTICIPANTES!$L$5:$L$504,"Sí") | E12: =COUNTIFS(PARTICIPANTES!$C$5:$C$504,$A12,PARTICIPANTES!$L$5:$L$504,"Sí",PARTICIPANTES!$Q$5:$Q$504,"Sí") | F12: =IF(E12<=1,"-",IF(E12<=4,4,IF(E12<=8,8,IF(E12<=16,16,32)))) | G12: =IF(F12=4,"Final",IF(F12=8,"Semifinal",IF(F12=16,"Octavas",IF(F12=32,"Eliminatoria","-")))) | H12: =IF(OR(F12="-",E12=0),0,F12-E12) | I12: =IF(E12=0,"⚪ Sin inscritos",IF(E12=1,"⚠ Solo 1 inscrito",IF(E12<4,"🟡 Pocos inscritos","🟢 Lista")))
A13: L09 | B13: Adulto-C · Masculino | C13: Jogo | D13: =COUNTIFS(PARTICIPANTES!$C$5:$C$504,$A13,PARTICIPANTES!$L$5:$L$504,"Sí") | E13: =COUNTIFS(PARTICIPANTES!$C$5:$C$504,$A13,PARTICIPANTES!$L$5:$L$504,"Sí",PARTICIPANTES!$Q$5:$Q$504,"Sí") | F13: =IF(E13<=1,"-",IF(E13<=4,4,IF(E13<=8,8,IF(E13<=16,16,32)))) | G13: =IF(F13=4,"Final",IF(F13=8,"Semifinal",IF(F13=16,"Octavas",IF(F13=32,"Eliminatoria","-")))) | H13: =IF(OR(F13="-",E13=0),0,F13-E13) | I13: =IF(E13=0,"⚪ Sin inscritos",IF(E13=1,"⚠ Solo 1 inscrito",IF(E13<4,"🟡 Pocos inscritos","🟢 Lista")))
A14: L10 | B14: Adulto-C · Femenino | C14: Jogo | D14: =COUNTIFS(PARTICIPANTES!$C$5:$C$504,$A14,PARTICIPANTES!$L$5:$L$504,"Sí") | E14: =COUNTIFS(PARTICIPANTES!$C$5:$C$504,$A14,PARTICIPANTES!$L$5:$L$504,"Sí",PARTICIPANTES!$Q$5:$Q$504,"Sí") | F14: =IF(E14<=1,"-",IF(E14<=4,4,IF(E14<=8,8,IF(E14<=16,16,32)))) | G14: =IF(F14=4,"Final",IF(F14=8,"Semifinal",IF(F14=16,"Octavas",IF(F14=32,"Eliminatoria","-")))) | H14: =IF(OR(F14="-",E14=0),0,F14-E14) | I14: =IF(E14=0,"⚪ Sin inscritos",IF(E14=1,"⚠ Solo 1 inscrito",IF(E14<4,"🟡 Pocos inscritos","🟢 Lista")))
A15: L11 | B15: Adulto-D · Masculino | C15: Jogo | D15: =COUNTIFS(PARTICIPANTES!$C$5:$C$504,$A15,PARTICIPANTES!$L$5:$L$504,"Sí") | E15: =COUNTIFS(PARTICIPANTES!$C$5:$C$504,$A15,PARTICIPANTES!$L$5:$L$504,"Sí",PARTICIPANTES!$Q$5:$Q$504,"Sí") | F15: =IF(E15<=1,"-",IF(E15<=4,4,IF(E15<=8,8,IF(E15<=16,16,32)))) | G15: =IF(F15=4,"Final",IF(F15=8,"Semifinal",IF(F15=16,"Octavas",IF(F15=32,"Eliminatoria","-")))) | H15: =IF(OR(F15="-",E15=0),0,F15-E15) | I15: =IF(E15=0,"⚪ Sin inscritos",IF(E15=1,"⚠ Solo 1 inscrito",IF(E15<4,"🟡 Pocos inscritos","🟢 Lista")))
A16: L12 | B16: Adulto-D · Femenino | C16: Jogo | D16: =COUNTIFS(PARTICIPANTES!$C$5:$C$504,$A16,PARTICIPANTES!$L$5:$L$504,"Sí") | E16: =COUNTIFS(PARTICIPANTES!$C$5:$C$504,$A16,PARTICIPANTES!$L$5:$L$504,"Sí",PARTICIPANTES!$Q$5:$Q$504,"Sí") | F16: =IF(E16<=1,"-",IF(E16<=4,4,IF(E16<=8,8,IF(E16<=16,16,32)))) | G16: =IF(F16=4,"Final",IF(F16=8,"Semifinal",IF(F16=16,"Octavas",IF(F16=32,"Eliminatoria","-")))) | H16: =IF(OR(F16="-",E16=0),0,F16-E16) | I16: =IF(E16=0,"⚪ Sin inscritos",IF(E16=1,"⚠ Solo 1 inscrito",IF(E16<4,"🟡 Pocos inscritos","🟢 Lista")))
... A22: L18 | B22: Baobá-Graduados+ · Femenino | C22: Jogo | D22: =COUNTIFS(PARTICIPANTES!$C$5:$C$504,$A22,PARTICIPANTES!$L$5:$L$504,"Sí") | E22: =COUNTIFS(PARTICIPANTES!$C$5:$C$504,$A22,PARTICIPANTES!$L$5:$L$504,"Sí",PARTICIPANTES!$Q$5:$Q$504,"Sí") | F22: =IF(E22<=1,"-",IF(E22<=4,4,IF(E22<=8,8,IF(E22<=16,16,32)))) | G22: =IF(F22=4,"Final",IF(F22=8,"Semifinal",IF(F22=16,"Octavas",IF(F22=32,"Eliminatoria","-")))) | H22: =IF(OR(F22="-",E22=0),0,F22-E22) | I22: =IF(E22=0,"⚪ Sin inscritos",IF(E22=1,"⚠ Solo 1 inscrito",IF(E22<4,"🟡 Pocos inscritos","🟢 Lista")))
A23: L19 | B23: Festival · Interpretación · Mixto | C23: Festival | D23: =COUNTIFS(PARTICIPANTES!$N$5:$N$504,"Interpretación",PARTICIPANTES!$M$5:$M$504,"Sí") | E23: =COUNTIFS(PARTICIPANTES!$N$5:$N$504,"Interpretación",PARTICIPANTES!$M$5:$M$504,"Sí",PARTICIPANTES!$Q$5:$Q$504,"Sí") | F23: =IF(E23<=1,"-",IF(E23<=4,4,IF(E23<=8,8,IF(E23<=16,16,32)))) | G23: =IF(F23=4,"Final",IF(F23=8,"Semifinal",IF(F23=16,"Octavas",IF(F23=32,"Eliminatoria","-")))) | H23: =IF(OR(F23="-",E23=0),0,F23-E23) | I23: =IF(E23=0,"⚪ Sin inscritos",IF(E23=1,"⚠ Solo 1 inscrito",IF(E23<4,"🟡 Pocos inscritos","🟢 Lista")))
A24: L20 | B24: Festival · Composición · Mixto | C24: Festival | D24: =COUNTIFS(PARTICIPANTES!$N$5:$N$504,"Composición",PARTICIPANTES!$M$5:$M$504,"Sí") | E24: =COUNTIFS(PARTICIPANTES!$N$5:$N$504,"Composición",PARTICIPANTES!$M$5:$M$504,"Sí",PARTICIPANTES!$Q$5:$Q$504,"Sí") | F24: =IF(E24<=1,"-",IF(E24<=4,4,IF(E24<=8,8,IF(E24<=16,16,32)))) | G24: =IF(F24=4,"Final",IF(F24=8,"Semifinal",IF(F24=16,"Octavas",IF(F24=32,"Eliminatoria","-")))) | H24: =IF(OR(F24="-",E24=0),0,F24-E24) | I24: =IF(E24=0,"⚪ Sin inscritos",IF(E24=1,"⚠ Solo 1 inscrito",IF(E24<4,"🟡 Pocos inscritos","🟢 Lista")))
A25: L21 | B25: Festival · Sólo Instrumento · Mixto | C25: Festival | D25: =COUNTIFS(PARTICIPANTES!$N$5:$N$504,"Sólo Instrumento",PARTICIPANTES!$M$5:$M$504,"Sí") | E25: =COUNTIFS(PARTICIPANTES!$N$5:$N$504,"Sólo Instrumento",PARTICIPANTES!$M$5:$M$504,"Sí",PARTICIPANTES!$Q$5:$Q$504,"Sí") | F25: =IF(E25<=1,"-",IF(E25<=4,4,IF(E25<=8,8,IF(E25<=16,16,32)))) | G25: =IF(F25=4,"Final",IF(F25=8,"Semifinal",IF(F25=16,"Octavas",IF(F25=32,"Eliminatoria","-")))) | H25: =IF(OR(F25="-",E25=0),0,F25-E25) | I25: =IF(E25=0,"⚪ Sin inscritos",IF(E25=1,"⚠ Solo 1 inscrito",IF(E25<4,"🟡 Pocos inscritos","🟢 Lista")))
A26: L22 | B26: Festival · Bateranga · Mixto | C26: Festival | D26: =COUNTIFS(PARTICIPANTES!$N$5:$N$504,"Bateranga",PARTICIPANTES!$M$5:$M$504,"Sí") | E26: =COUNTIFS(PARTICIPANTES!$N$5:$N$504,"Bateranga",PARTICIPANTES!$M$5:$M$504,"Sí",PARTICIPANTES!$Q$5:$Q$504,"Sí") | F26: =IF(E26<=1,"-",IF(E26<=4,4,IF(E26<=8,8,IF(E26<=16,16,32)))) | G26: =IF(F26=4,"Final",IF(F26=8,"Semifinal",IF(F26=16,"Octavas",IF(F26=32,"Eliminatoria","-")))) | H26: =IF(OR(F26="-",E26=0),0,F26-E26) | I26: =IF(E26=0,"⚪ Sin inscritos",IF(E26=1,"⚠ Solo 1 inscrito",IF(E26<4,"🟡 Pocos inscritos","🟢 Lista")))
B27: TOTAL | D27: =SUM(D5:D26) | E27: =SUM(E5:E26)

Sheet TORNEO_ACTIVO
A1: TORNEO_ACTIVO · Selecciona una llave y se carga el bracket
A3: ID Llave: | B3: L09
A4: Categoría: | B4: =IFERROR(VLOOKUP($B$3,LLAVES_INDEX!$A$5:$K$26,2,FALSE()),"")
A5: Tipo: | B5: =IFERROR(VLOOKUP($B$3,LLAVES_INDEX!$A$5:$K$26,3,FALSE()),"")
A6: Inscritos activos: | B6: =IFERROR(VLOOKUP($B$3,LLAVES_INDEX!$A$5:$K$26,5,FALSE()),"")
A7: Tamaño llave: | B7: =IFERROR(VLOOKUP($B$3,LLAVES_INDEX!$A$5:$K$26,6,FALSE()),"")
A8: Ronda inicial: | B8: =IFERROR(VLOOKUP($B$3,LLAVES_INDEX!$A$5:$K$26,7,FALSE()),"")
A9: BYEs: | B9: =IFERROR(VLOOKUP($B$3,LLAVES_INDEX!$A$5:$K$26,8,FALSE()),"")
A11: POSICIONES SEEDED (1 = mejor corda / 32 = peor o BYE)
A12: Pos. | B12: Participante | C12: Corda | D12: Orden corda | E12: Estado
A13: 1 | B13: {=IFERROR(IF(LARGE(PARTICIPANTES!$R$5:$R$504,1)>0,INDEX(PARTICIPANTES!$E$5:$E$504,MATCH(LARGE(PARTICIPANTES!$R$5:$R$504,1),PARTICIPANTES!$R$5:$R$504,0)),"BYE"),"BYE")} | C13: {=IFERROR(IF(LARGE(PARTICIPANTES!$R$5:$R$504,1)>0,INDEX(PARTICIPANTES!$F$5:$F$504,MATCH(LARGE(PARTICIPANTES!$R$5:$R$504,1),PARTICIPANTES!$R$5:$R$504,0)),""),"")} | D13: {=IFERROR(IF(LARGE(PARTICIPANTES!$R$5:$R$504,1)>0,INDEX(PARTICIPANTES!$G$5:$G$504,MATCH(LARGE(PARTICIPANTES!$R$5:$R$504,1),PARTICIPANTES!$R$5:$R$504,0)),0),0)} | E13: =IF(B13="BYE","🚫 BYE","✓ Activo")
A14: 2 | B14: {=IFERROR(IF(LARGE(PARTICIPANTES!$R$5:$R$504,2)>0,INDEX(PARTICIPANTES!$E$5:$E$504,MATCH(LARGE(PARTICIPANTES!$R$5:$R$504,2),PARTICIPANTES!$R$5:$R$504,0)),"BYE"),"BYE")} | C14: {=IFERROR(IF(LARGE(PARTICIPANTES!$R$5:$R$504,2)>0,INDEX(PARTICIPANTES!$F$5:$F$504,MATCH(LARGE(PARTICIPANTES!$R$5:$R$504,2),PARTICIPANTES!$R$5:$R$504,0)),""),"")} | D14: {=IFERROR(IF(LARGE(PARTICIPANTES!$R$5:$R$504,2)>0,INDEX(PARTICIPANTES!$G$5:$G$504,MATCH(LARGE(PARTICIPANTES!$R$5:$R$504,2),PARTICIPANTES!$R$5:$R$504,0)),0),0)} | E14: =IF(B14="BYE","🚫 BYE","✓ Activo")
A15: 3 | B15: {=IFERROR(IF(LARGE(PARTICIPANTES!$R$5:$R$504,3)>0,INDEX(PARTICIPANTES!$E$5:$E$504,MATCH(LARGE(PARTICIPANTES!$R$5:$R$504,3),PARTICIPANTES!$R$5:$R$504,0)),"BYE"),"BYE")} | C15: {=IFERROR(IF(LARGE(PARTICIPANTES!$R$5:$R$504,3)>0,INDEX(PARTICIPANTES!$F$5:$F$504,MATCH(LARGE(PARTICIPANTES!$R$5:$R$504,3),PARTICIPANTES!$R$5:$R$504,0)),""),"")} | D15: {=IFERROR(IF(LARGE(PARTICIPANTES!$R$5:$R$504,3)>0,INDEX(PARTICIPANTES!$G$5:$G$504,MATCH(LARGE(PARTICIPANTES!$R$5:$R$504,3),PARTICIPANTES!$R$5:$R$504,0)),0),0)} | E15: =IF(B15="BYE","🚫 BYE","✓ Activo")
A16: 4 | B16: {=IFERROR(IF(LARGE(PARTICIPANTES!$R$5:$R$504,4)>0,INDEX(PARTICIPANTES!$E$5:$E$504,MATCH(LARGE(PARTICIPANTES!$R$5:$R$504,4),PARTICIPANTES!$R$5:$R$504,0)),"BYE"),"BYE")} | C16: {=IFERROR(IF(LARGE(PARTICIPANTES!$R$5:$R$504,4)>0,INDEX(PARTICIPANTES!$F$5:$F$504,MATCH(LARGE(PARTICIPANTES!$R$5:$R$504,4),PARTICIPANTES!$R$5:$R$504,0)),""),"")} | D16: {=IFERROR(IF(LARGE(PARTICIPANTES!$R$5:$R$504,4)>0,INDEX(PARTICIPANTES!$G$5:$G$504,MATCH(LARGE(PARTICIPANTES!$R$5:$R$504,4),PARTICIPANTES!$R$5:$R$504,0)),0),0)} | E16: =IF(B16="BYE","🚫 BYE","✓ Activo")
A17: 5 | B17: {=IFERROR(IF(LARGE(PARTICIPANTES!$R$5:$R$504,5)>0,INDEX(PARTICIPANTES!$E$5:$E$504,MATCH(LARGE(PARTICIPANTES!$R$5:$R$504,5),PARTICIPANTES!$R$5:$R$504,0)),"BYE"),"BYE")} | C17: {=IFERROR(IF(LARGE(PARTICIPANTES!$R$5:$R$504,5)>0,INDEX(PARTICIPANTES!$F$5:$F$504,MATCH(LARGE(PARTICIPANTES!$R$5:$R$504,5),PARTICIPANTES!$R$5:$R$504,0)),""),"")} | D17: {=IFERROR(IF(LARGE(PARTICIPANTES!$R$5:$R$504,5)>0,INDEX(PARTICIPANTES!$G$5:$G$504,MATCH(LARGE(PARTICIPANTES!$R$5:$R$504,5),PARTICIPANTES!$R$5:$R$504,0)),0),0)} | E17: =IF(B17="BYE","🚫 BYE","✓ Activo")
A18: 6 | B18: {=IFERROR(IF(LARGE(PARTICIPANTES!$R$5:$R$504,6)>0,INDEX(PARTICIPANTES!$E$5:$E$504,MATCH(LARGE(PARTICIPANTES!$R$5:$R$504,6),PARTICIPANTES!$R$5:$R$504,0)),"BYE"),"BYE")} | C18: {=IFERROR(IF(LARGE(PARTICIPANTES!$R$5:$R$504,6)>0,INDEX(PARTICIPANTES!$F$5:$F$504,MATCH(LARGE(PARTICIPANTES!$R$5:$R$504,6),PARTICIPANTES!$R$5:$R$504,0)),""),"")} | D18: {=IFERROR(IF(LARGE(PARTICIPANTES!$R$5:$R$504,6)>0,INDEX(PARTICIPANTES!$G$5:$G$504,MATCH(LARGE(PARTICIPANTES!$R$5:$R$504,6),PARTICIPANTES!$R$5:$R$504,0)),0),0)} | E18: =IF(B18="BYE","🚫 BYE","✓ Activo")
A19: 7 | B19: {=IFERROR(IF(LARGE(PARTICIPANTES!$R$5:$R$504,7)>0,INDEX(PARTICIPANTES!$E$5:$E$504,MATCH(LARGE(PARTICIPANTES!$R$5:$R$504,7),PARTICIPANTES!$R$5:$R$504,0)),"BYE"),"BYE")} | C19: {=IFERROR(IF(LARGE(PARTICIPANTES!$R$5:$R$504,7)>0,INDEX(PARTICIPANTES!$F$5:$F$504,MATCH(LARGE(PARTICIPANTES!$R$5:$R$504,7),PARTICIPANTES!$R$5:$R$504,0)),""),"")} | D19: {=IFERROR(IF(LARGE(PARTICIPANTES!$R$5:$R$504,7)>0,INDEX(PARTICIPANTES!$G$5:$G$504,MATCH(LARGE(PARTICIPANTES!$R$5:$R$504,7),PARTICIPANTES!$R$5:$R$504,0)),0),0)} | E19: =IF(B19="BYE","🚫 BYE","✓ Activo")
A20: 8 | B20: {=IFERROR(IF(LARGE(PARTICIPANTES!$R$5:$R$504,8)>0,INDEX(PARTICIPANTES!$E$5:$E$504,MATCH(LARGE(PARTICIPANTES!$R$5:$R$504,8),PARTICIPANTES!$R$5:$R$504,0)),"BYE"),"BYE")} | C20: {=IFERROR(IF(LARGE(PARTICIPANTES!$R$5:$R$504,8)>0,INDEX(PARTICIPANTES!$F$5:$F$504,MATCH(LARGE(PARTICIPANTES!$R$5:$R$504,8),PARTICIPANTES!$R$5:$R$504,0)),""),"")} | D20: {=IFERROR(IF(LARGE(PARTICIPANTES!$R$5:$R$504,8)>0,INDEX(PARTICIPANTES!$G$5:$G$504,MATCH(LARGE(PARTICIPANTES!$R$5:$R$504,8),PARTICIPANTES!$R$5:$R$504,0)),0),0)} | E20: =IF(B20="BYE","🚫 BYE","✓ Activo")
A21: 9 | B21: {=IFERROR(IF(LARGE(PARTICIPANTES!$R$5:$R$504,9)>0,INDEX(PARTICIPANTES!$E$5:$E$504,MATCH(LARGE(PARTICIPANTES!$R$5:$R$504,9),PARTICIPANTES!$R$5:$R$504,0)),"BYE"),"BYE")} | C21: {=IFERROR(IF(LARGE(PARTICIPANTES!$R$5:$R$504,9)>0,INDEX(PARTICIPANTES!$F$5:$F$504,MATCH(LARGE(PARTICIPANTES!$R$5:$R$504,9),PARTICIPANTES!$R$5:$R$504,0)),""),"")} | D21: {=IFERROR(IF(LARGE(PARTICIPANTES!$R$5:$R$504,9)>0,INDEX(PARTICIPANTES!$G$5:$G$504,MATCH(LARGE(PARTICIPANTES!$R$5:$R$504,9),PARTICIPANTES!$R$5:$R$504,0)),0),0)} | E21: =IF(B21="BYE","🚫 BYE","✓ Activo")
A22: 10 | B22: {=IFERROR(IF(LARGE(PARTICIPANTES!$R$5:$R$504,10)>0,INDEX(PARTICIPANTES!$E$5:$E$504,MATCH(LARGE(PARTICIPANTES!$R$5:$R$504,10),PARTICIPANTES!$R$5:$R$504,0)),"BYE"),"BYE")} | C22: {=IFERROR(IF(LARGE(PARTICIPANTES!$R$5:$R$504,10)>0,INDEX(PARTICIPANTES!$F$5:$F$504,MATCH(LARGE(PARTICIPANTES!$R$5:$R$504,10),PARTICIPANTES!$R$5:$R$504,0)),""),"")} | D22: {=IFERROR(IF(LARGE(PARTICIPANTES!$R$5:$R$504,10)>0,INDEX(PARTICIPANTES!$G$5:$G$504,MATCH(LARGE(PARTICIPANTES!$R$5:$R$504,10),PARTICIPANTES!$R$5:$R$504,0)),0),0)} | E22: =IF(B22="BYE","🚫 BYE","✓ Activo")
A23: 11 | B23: {=IFERROR(IF(LARGE(PARTICIPANTES!$R$5:$R$504,11)>0,INDEX(PARTICIPANTES!$E$5:$E$504,MATCH(LARGE(PARTICIPANTES!$R$5:$R$504,11),PARTICIPANTES!$R$5:$R$504,0)),"BYE"),"BYE")} | C23: {=IFERROR(IF(LARGE(PARTICIPANTES!$R$5:$R$504,11)>0,INDEX(PARTICIPANTES!$F$5:$F$504,MATCH(LARGE(PARTICIPANTES!$R$5:$R$504,11),PARTICIPANTES!$R$5:$R$504,0)),""),"")} | D23: {=IFERROR(IF(LARGE(PARTICIPANTES!$R$5:$R$504,11)>0,INDEX(PARTICIPANTES!$G$5:$G$504,MATCH(LARGE(PARTICIPANTES!$R$5:$R$504,11),PARTICIPANTES!$R$5:$R$504,0)),0),0)} | E23: =IF(B23="BYE","🚫 BYE","✓ Activo")
A24: 12 | B24: {=IFERROR(IF(LARGE(PARTICIPANTES!$R$5:$R$504,12)>0,INDEX(PARTICIPANTES!$E$5:$E$504,MATCH(LARGE(PARTICIPANTES!$R$5:$R$504,12),PARTICIPANTES!$R$5:$R$504,0)),"BYE"),"BYE")} | C24: {=IFERROR(IF(LARGE(PARTICIPANTES!$R$5:$R$504,12)>0,INDEX(PARTICIPANTES!$F$5:$F$504,MATCH(LARGE(PARTICIPANTES!$R$5:$R$504,12),PARTICIPANTES!$R$5:$R$504,0)),""),"")} | D24: {=IFERROR(IF(LARGE(PARTICIPANTES!$R$5:$R$504,12)>0,INDEX(PARTICIPANTES!$G$5:$G$504,MATCH(LARGE(PARTICIPANTES!$R$5:$R$504,12),PARTICIPANTES!$R$5:$R$504,0)),0),0)} | E24: =IF(B24="BYE","🚫 BYE","✓ Activo")
A25: 13 | B25: {=IFERROR(IF(LARGE(PARTICIPANTES!$R$5:$R$504,13)>0,INDEX(PARTICIPANTES!$E$5:$E$504,MATCH(LARGE(PARTICIPANTES!$R$5:$R$504,13),PARTICIPANTES!$R$5:$R$504,0)),"BYE"),"BYE")} | C25: {=IFERROR(IF(LARGE(PARTICIPANTES!$R$5:$R$504,13)>0,INDEX(PARTICIPANTES!$F$5:$F$504,MATCH(LARGE(PARTICIPANTES!$R$5:$R$504,13),PARTICIPANTES!$R$5:$R$504,0)),""),"")} | D25: {=IFERROR(IF(LARGE(PARTICIPANTES!$R$5:$R$504,13)>0,INDEX(PARTICIPANTES!$G$5:$G$504,MATCH(LARGE(PARTICIPANTES!$R$5:$R$504,13),PARTICIPANTES!$R$5:$R$504,0)),0),0)} | E25: =IF(B25="BYE","🚫 BYE","✓ Activo")
A26: 14 | B26: {=IFERROR(IF(LARGE(PARTICIPANTES!$R$5:$R$504,14)>0,INDEX(PARTICIPANTES!$E$5:$E$504,MATCH(LARGE(PARTICIPANTES!$R$5:$R$504,14),PARTICIPANTES!$R$5:$R$504,0)),"BYE"),"BYE")} | C26: {=IFERROR(IF(LARGE(PARTICIPANTES!$R$5:$R$504,14)>0,INDEX(PARTICIPANTES!$F$5:$F$504,MATCH(LARGE(PARTICIPANTES!$R$5:$R$504,14),PARTICIPANTES!$R$5:$R$504,0)),""),"")} | D26: {=IFERROR(IF(LARGE(PARTICIPANTES!$R$5:$R$504,14)>0,INDEX(PARTICIPANTES!$G$5:$G$504,MATCH(LARGE(PARTICIPANTES!$R$5:$R$504,14),PARTICIPANTES!$R$5:$R$504,0)),0),0)} | E26: =IF(B26="BYE","🚫 BYE","✓ Activo")
A27: 15 | B27: {=IFERROR(IF(LARGE(PARTICIPANTES!$R$5:$R$504,15)>0,INDEX(PARTICIPANTES!$E$5:$E$504,MATCH(LARGE(PARTICIPANTES!$R$5:$R$504,15),PARTICIPANTES!$R$5:$R$504,0)),"BYE"),"BYE")} | C27: {=IFERROR(IF(LARGE(PARTICIPANTES!$R$5:$R$504,15)>0,INDEX(PARTICIPANTES!$F$5:$F$504,MATCH(LARGE(PARTICIPANTES!$R$5:$R$504,15),PARTICIPANTES!$R$5:$R$504,0)),""),"")} | D27: {=IFERROR(IF(LARGE(PARTICIPANTES!$R$5:$R$504,15)>0,INDEX(PARTICIPANTES!$G$5:$G$504,MATCH(LARGE(PARTICIPANTES!$R$5:$R$504,15),PARTICIPANTES!$R$5:$R$504,0)),0),0)} | E27: =IF(B27="BYE","🚫 BYE","✓ Activo")
A28: 16 | B28: {=IFERROR(IF(LARGE(PARTICIPANTES!$R$5:$R$504,16)>0,INDEX(PARTICIPANTES!$E$5:$E$504,MATCH(LARGE(PARTICIPANTES!$R$5:$R$504,16),PARTICIPANTES!$R$5:$R$504,0)),"BYE"),"BYE")} | C28: {=IFERROR(IF(LARGE(PARTICIPANTES!$R$5:$R$504,16)>0,INDEX(PARTICIPANTES!$F$5:$F$504,MATCH(LARGE(PARTICIPANTES!$R$5:$R$504,16),PARTICIPANTES!$R$5:$R$504,0)),""),"")} | D28: {=IFERROR(IF(LARGE(PARTICIPANTES!$R$5:$R$504,16)>0,INDEX(PARTICIPANTES!$G$5:$G$504,MATCH(LARGE(PARTICIPANTES!$R$5:$R$504,16),PARTICIPANTES!$R$5:$R$504,0)),0),0)} | E28: =IF(B28="BYE","🚫 BYE","✓ Activo")
